Traceback (most recent call last):
  File "/glade/u/apps/opt/conda/envs/npl-2024a/lib/python3.11/site-packages/jupyter_cache/executors/utils.py", line 58, in single_nb_execution
    executenb(
  File "/glade/u/apps/opt/conda/envs/npl-2024a/lib/python3.11/site-packages/nbclient/client.py", line 1305, in execute
    return NotebookClient(nb=nb, resources=resources, km=km, **kwargs).execute()
           ^^^^^^^^^^^^^^^^^^^^^^^^^^^^^^^^^^^^^^^^^^^^^^^^^^^^^^^^^^^^^^^^^^^^^
  File "/glade/u/apps/opt/conda/envs/npl-2024a/lib/python3.11/site-packages/jupyter_core/utils/__init__.py", line 165, in wrapped
    return loop.run_until_complete(inner)
           ^^^^^^^^^^^^^^^^^^^^^^^^^^^^^^
  File "/glade/u/apps/opt/conda/envs/npl-2024a/lib/python3.11/asyncio/base_events.py", line 653, in run_until_complete
    return future.result()
           ^^^^^^^^^^^^^^^
  File "/glade/u/apps/opt/conda/envs/npl-2024a/lib/python3.11/site-packages/nbclient/client.py", line 705, in async_execute
    await self.async_execute_cell(
  File "/glade/u/apps/opt/conda/envs/npl-2024a/lib/python3.11/site-packages/nbclient/client.py", line 1058, in async_execute_cell
    await self._check_raise_for_error(cell, cell_index, exec_reply)
  File "/glade/u/apps/opt/conda/envs/npl-2024a/lib/python3.11/site-packages/nbclient/client.py", line 914, in _check_raise_for_error
    raise CellExecutionError.from_cell_and_msg(cell, exec_reply_content)
nbclient.exceptions.CellExecutionError: An error occurred while executing the following cell:
------------------
ds_PI = xr.open_mfdataset(files_PI)
ds_MH = xr.open_mfdataset(files_MH)

# We need this fix to get the correct time, i.e., January to December of year 1
ds_PI['time'] = ds_PI.time.get_index('time') - timedelta(days=15)
ds_MH['time'] = ds_MH.time.get_index('time') - timedelta(days=15)
------------------


[0;31m---------------------------------------------------------------------------[0m
[0;31mOSError[0m                                   Traceback (most recent call last)
Cell [0;32mIn[5], line 1[0m
[0;32m----> 1[0m ds_PI [38;5;241m=[39m [43mxr[49m[38;5;241;43m.[39;49m[43mopen_mfdataset[49m[43m([49m[43mfiles_PI[49m[43m)[49m
[1;32m      2[0m ds_MH [38;5;241m=[39m xr[38;5;241m.[39mopen_mfdataset(files_MH)
[1;32m      4[0m [38;5;66;03m# We need this fix to get the correct time, i.e., January to December of year 1[39;00m

File [0;32m/glade/u/apps/opt/conda/envs/npl-2024a/lib/python3.11/site-packages/xarray/backends/api.py:990[0m, in [0;36mopen_mfdataset[0;34m(paths, chunks, concat_dim, compat, preprocess, engine, data_vars, coords, combine, parallel, join, attrs_file, combine_attrs, **kwargs)[0m
[1;32m    987[0m paths [38;5;241m=[39m _find_absolute_paths(paths, engine[38;5;241m=[39mengine, [38;5;241m*[39m[38;5;241m*[39mkwargs)
[1;32m    989[0m [38;5;28;01mif[39;00m [38;5;129;01mnot[39;00m paths:
[0;32m--> 990[0m     [38;5;28;01mraise[39;00m [38;5;167;01mOSError[39;00m([38;5;124m"[39m[38;5;124mno files to open[39m[38;5;124m"[39m)
[1;32m    992[0m [38;5;28;01mif[39;00m combine [38;5;241m==[39m [38;5;124m"[39m[38;5;124mnested[39m[38;5;124m"[39m:
[1;32m    993[0m     [38;5;28;01mif[39;00m [38;5;28misinstance[39m(concat_dim, ([38;5;28mstr[39m, DataArray)) [38;5;129;01mor[39;00m concat_dim [38;5;129;01mis[39;00m [38;5;28;01mNone[39;00m:

[0;31mOSError[0m: no files to open

